Workbook

Sheet 決算入力
K1: コード | L1: 銘柄名 | N1: 決算年 | O1: 決算月 | P1: 更新日
K2: 2206 | L2: 江崎グリコ株式会社 | N2: 2025 | O2: 12 | P2: =NOW() -> 46080.831
A3: ■時系列決算データ比較
C4: =LEFT(F4,4)-1&"年" -> 2021年 | D4: =G4 -> 12 月期 | E4: 構成比 | F4: =LEFT(I4,4)-1&"年" -> 2022年 | G4: =J4 -> 12 月期 | H4: 構成比 | I4: =LEFT(L4,4)-1&"年" -> 2023年 | J4: =M4 -> 12 月期 | K4: 構成比 | L4: =LEFT(O4,4)-1&"年" -> 2024年 | M4: =P4 -> 12 月期 | N4: 構成比 | O4: =N2 &" 年" -> 2025 年 | P4: =O2 &" 月期" -> 12 月期 | Q4: 構成比
B5: 売上高 | D5: 338571 | E5: 百万 | G5: 303921 | H5: =E5 -> 百万 | J5: 332590 | K5: =E5 -> 百万 | M5: 331129 | N5: =E5 -> 百万 | P5: =IF(P30,P30,IF(M30,M30,IF(J30,J30,IF(G30,G30,IF(D30,D30,0))))) -> 0 | Q5: =H5 -> 百万
B6: 売上原価 | D6: 180537 | E6: =IF(D$5,D6/D$5,"-") -> 0.53323232 | G6: 193172 | H6: =IF(G$5,G6/G$5,"-") -> 0.63559938 | J6: 208740 | K6: =IF(J$5,J6/J$5,"-") -> 0.62761959 | M6: 203461 | N6: =IF(M$5,M6/M$5,"-") -> 0.61444633 | Q6: =IF(P$5,P6/P$5,"-") -> -
B7: 売上総利益 | D7: 158033 | E7: =IF(D$5,D7/D$5,"-") -> 0.46676473 | G7: 110749 | H7: =IF(G$5,G7/G$5,"-") -> 0.36440062 | J7: 123850 | K7: =IF(J$5,J7/J$5,"-") -> 0.37238041 | M7: 127668 | N7: =IF(M$5,M7/M$5,"-") -> 0.38555367 | Q7: =IF(P$5,P7/P$5,"-") -> -
B8: 販管費 | D8: 138726 | E8: =IF(D$5,D8/D$5,"-") -> 0.40973976 | G8: 97903 | H8: =IF(G$5,G8/G$5,"-") -> 0.32213305 | J8: 105228 | K8: =IF(J$5,J8/J$5,"-") -> 0.31638955 | M8: 116602 | N8: =IF(M$5,M8/M$5,"-") -> 0.35213467 | Q8: =IF(P$5,P8/P$5,"-") -> -
B9: 営業利益 | D9: 19307 | E9: =IF(D$5,D9/D$5,"-") -> 0.057024967 | G9: 12845 | H9: =IF(G$5,G9/G$5,"-") -> 0.042264273 | J9: 18622 | K9: =IF(J$5,J9/J$5,"-") -> 0.05599086 | M9: 11065 | N9: =IF(M$5,M9/M$5,"-") -> 0.03341598 | Q9: =IF(P$5,P9/P$5,"-") -> -
B10: 経常利益 | D10: 21708 | E10: =IF(D$5,D10/D$5,"-") -> 0.064116537 | G10: 13646 | H10: =IF(G$5,G10/G$5,"-") -> 0.044899826 | J10: 21285 | K10: =IF(J$5,J10/J$5,"-") -> 0.063997715 | M10: 13348 | N10: =IF(M$5,M10/M$5,"-") -> 0.040310574 | P10: =IF(P31,P31,IF(M31,M31,IF(J31,J31,IF(G31,G31,IF(D31,D31,0))))) -> 0 | Q10: =IF(P$5,P10/P$5,"-") -> -
B11: 純利益 | D11: 13567 | E11: =IF(D$5,D11/D$5,"-") -> 0.040071359 | G11: 8156 | H11: =IF(G$5,G11/G$5,"-") -> 0.026835921 | J11: 14219 | K11: =IF(J$5,J11/J$5,"-") -> 0.042752338 | M11: 8157 | N11: =IF(M$5,M11/M$5,"-") -> 0.024633904 | P11: =IF(P32,P32,IF(M32,M32,IF(J32,J32,IF(G32,G32,IF(D32,D32,0))))) -> 0 | Q11: =IF(P$5,P11/P$5,"-") -> -
B13: 発行株数 | D13: 68468 | E13: 千株 | G13: 68468 | H13: =E13 -> 千株 | J13: 68468 | K13: =H13 -> 千株 | M13: 68468 | N13: =K13 -> 千株 | P13: =IF(P40,P40,IF(M40,M40,IF(J40,J40,IF(G40,G40,IF(D40,D40,0))))) -> 68468 | Q13: =N13 -> 千株
B14: EPS／PER | D14: =IF(D13,D10*1000*0.7/D13,0) -> 221.93726 | E14: =IF(D14,D26/D14,0) -> 0 | G14: =IF(G13,G10*1000*0.7/G13,0) -> 139.51335 | H14: =IF(G14,G26/G14,0) -> 0 | J14: =IF(J13,J10*1000*0.7/J13,0) -> 217.61261 | K14: =IF(J14,J26/J14,0) -> 0 | M14: =IF(M13,M10*1000*0.7/M13,0) -> 136.46667 | N14: =IF(M14,M26/M14,0) -> 0 | P14: =IF(P13,P10*1000*0.7/P13,0) -> 0 | Q14: =IF(P14,P26/P14,0) -> 0
C16: 資産 | D16: 資本 | E16: 負債 | F16: 資産 | G16: 資本 | H16: 負債 | I16: 資産 | J16: 資本 | K16: 負債 | L16: 資産 | M16: 資本 | N16: 負債 | O16: 資産 | P16: 資本 | Q16: 負債
B17: バランスシート | C17: 356745 | D17: 241177 | E17: =C17-D17 -> 115568 | F17: 369056 | G17: 244760 | H17: =F17-G17 -> 124296 | I17: 395743 | J17: 263116 | K17: =I17-J17 -> 132627 | L17: 377771 | M17: 272598 | N17: =L17-M17 -> 105173 | O17: =IF(O44,O44,IF(L44,L44,IF(I44,I44,IF(F44,F44,IF(C44,C44,0))))) -> #VALUE! | P17: =IF(P44,P44,IF(M44,M44,IF(J44,J44,IF(G44,G44,IF(D44,D44,0))))) -> #VALUE! | Q17: =O17-P17 -> #VALUE!
B18: BPS／PBR | C18: =IF(C17,D17/C17,0) -> 0.67604872 | D18: =IF(D13,D17/D13*1000,0) -> 3522.4777 | E18: =IF(D18,D26/D18,0) -> 0 | F18: =IF(F17,G17/F17,0) -> 0.66320558 | G18: =IF(G13,G17/G13*1000,0) -> 3574.8087 | H18: =IF(G18,G26/G18,0) -> 0 | I18: =IF(I17,J17/I17,0) -> 0.66486583 | J18: =IF(J13,J17/J13*1000,0) -> 3842.9047 | K18: =IF(J18,J26/J18,0) -> 0 | L18: =IF(L17,M17/L17,0) -> 0.72159589 | M18: =IF(M13,M17/M13*1000,0) -> 3981.3928 | N18: =IF(M18,M26/M18,0) -> 0 | O18: =IF(O17,P17/O17,0) -> #VALUE! | P18: =IF(P13,P17/P13*1000,0) -> #VALUE! | Q18: =IF(P18,P26/P18,0) -> #VALUE!
B19: 財務レバレッジ補正 | C19: =IF(D17*C17>0,IF((1/(D17/C17+0.33))<1,1,IF((1/(D17/C17+0.33))>1.5,1.5,1/(D17/C17+0.33))),0) -> 1 | F19: =IF(G17*F17>0,IF((1/(G17/F17+0.33))<1,1,IF((1/(G17/F17+0.33))>1.5,1.5,1/(G17/F17+0.33))),0) -> 1.0068409 | I19: =IF(J17*I17>0,IF((1/(J17/I17+0.33))<1,1,IF((1/(J17/I17+0.33))>1.5,1.5,1/(J17/I17+0.33))),0) -> 1.0051607 | L19: =IF(M17*L17>0,IF((1/(M17/L17+0.33))<1,1,IF((1/(M17/L17+0.33))>1.5,1.5,1/(M17/L17+0.33))),0) -> 1 | O19: =IF(P17*O17>0,IF((1/(P17/O17+0.33))<1,1,IF((1/(P17/O17+0.33))>1.5,1.5,1/(P17/O17+0.33))),0) -> #VALUE!
C20: 営業 | D20: 投資 | E20: 財務 | F20: 営業 | G20: 投資 | H20: 財務 | I20: 営業 | J20: 投資 | K20: 財務 | L20: 営業 | M20: 投資 | N20: 財務 | O20: 営業 | P20: 投資 | Q20: 財務
B21: キャッシュフロー | C21: 28651 | D21: -29194 | E21: -4859 | F21: 16802 | G21: -20140 | H21: -10284 | I21: 28063 | J21: -8613 | K21: -6179 | L21: 1812 | M21: -10255 | N21: -39246 | O21: =IF(O48,O48,IF(L48,L48,IF(I48,I48,IF(F48,F48,IF(C48,C48,0))))) -> #VALUE! | P21: =IF(P48,P48,IF(M48,M48,IF(J48,J48,IF(G48,G48,IF(D48,D48,0))))) -> #VALUE! | Q21: =IF(Q48,Q48,IF(N48,N48,IF(K48,K48,IF(H48,H48,IF(E48,E48,0))))) -> #VALUE!
B22: 現金残／FCF | D22: 89463 | E22: =C21+D21 -> -543 | G22: 79917 | H22: =F21+G21 -> -3338 | J22: 94691 | K22: =I21+J21 -> 19450 | M22: 56610 | N22: =L21+M21 -> -8443 | P22: =IF(P49,P49,IF(M49,M49,IF(J49,J49,IF(G49,G49,IF(D49,D49,0))))) -> #VALUE! | Q22: =O21+P21 -> #VALUE!
C24: 資産価値 | D24: 事業価値 | E24: 理論株価 | F24: 資産価値 | G24: 事業価値 | H24: 理論株価 | I24: 資産価値 | J24: 事業価値 | K24: 理論株価 | L24: 資産価値 | M24: 事業価値 | N24: 理論株価 | O24: 資産価値 | P24: 事業価値 | Q24: 理論株価
B25: 理論株価 | C25: =D18*IF(C18>=0.8,0.8,IF(C18>=0.67,0.75,IF(C18>=0.5,0.7,IF(C18>=0.33,0.65,IF(C18>=0.1,0.6,0.5))))) -> 2641.8582 | D25: =IF(C19>0,IF(D10>0,IF(D14*C17,D14*(D10*0.7/C17*150),0),0)*C19,0) -> 1418.017 | E25: =C25+D25 -> 4059.8752 | F25: =G18*IF(F18>=0.8,0.8,IF(F18>=0.67,0.75,IF(F18>=0.5,0.7,IF(F18>=0.33,0.65,IF(F18>=0.1,0.6,0.5))))) -> 2502.3661 | G25: =IF(F19>0,IF(G10>0,IF(G14*F17,G14*(G10*0.7/F17*150),0),0)*F19,0) -> 545.35463 | H25: =F25+G25 -> 3047.7207 | I25: =J18*IF(I18>=0.8,0.8,IF(I18>=0.67,0.75,IF(I18>=0.5,0.7,IF(I18>=0.33,0.65,IF(I18>=0.1,0.6,0.5))))) -> 2690.0333 | J25: =IF(I19>0,IF(J10>0,IF(J14*I17,J14*(J10*0.7/I17*150),0),0)*I19,0) -> 1235.2909 | K25: =I25+J25 -> 3925.3242 | L25: =M18*IF(L18>=0.8,0.8,IF(L18>=0.67,0.75,IF(L18>=0.5,0.7,IF(L18>=0.33,0.65,IF(L18>=0.1,0.6,0.5))))) -> 2986.0446 | M25: =IF(L19>0,IF(M10>0,IF(M14*L17,M14*(M10*0.7/L17*150),0),0)*L19,0) -> 506.29481 | N25: =L25+M25 -> 3492.3394 | O25: =P18*IF(O18>=0.8,0.8,IF(O18>=0.67,0.75,IF(O18>=0.5,0.7,IF(O18>=0.33,0.65,IF(O18>=0.1,0.6,0.5))))) -> #VALUE! | P25: =IF(O19>0,IF(P10>0,IF(P14*O17,P14*(P10*0.7/O17*150),0),0)*O19,0) -> #VALUE! | Q25: =O25+P25 -> #VALUE!
B26: 株価／理論比 | C26: =DATE(LEFT(C4,4),LEFT(D4,LEN(D4)-2)+1,0) -> 44561 | E26: =IF(E25,D26/E25,0) -> 0 | F26: =DATE(LEFT(F4,4),LEFT(G4,LEN(G4)-2)+1,0) -> 44926 | H26: =IF(H25,G26/H25,0) -> 0 | I26: =DATE(LEFT(I4,4),LEFT(J4,LEN(J4)-2)+1,0) -> 45291 | K26: =IF(K25,J26/K25,0) -> 0 | L26: =DATE(LEFT(L4,4),LEFT(M4,LEN(M4)-2)+1,0) -> 45657 | N26: =IF(N25,M26/N25,0) -> 0 | O26: =IF(P53,O53,TODAY()) -> 46080 | P26: =IF(P53,P53,IF(M53,M53,IF(J53,J53,IF(G53,G53,IF(D53,D53,0))))) -> 0 | Q26: =IF(Q25,P26/Q25,0) -> #VALUE!
B27: 上限理論株価 | C27: =C25+(D25*2) -> 5477.8922 | F27: =F25+(G25*2) -> 3593.0753 | I27: =I25+(J25*2) -> 5160.6151 | L27: =L25+(M25*2) -> 3998.6342 | O27: =O25+(P25*2) -> #VALUE!
A28: ■今期会社予想
C29: 期初 | E29: 前期比 | F29: １Q | G29: =IF(G30>0,IF(G32>D32,"上方修正",IF(G32<D32,"下方修正","据え置き")),"") | H29: 前期比 | I29: ２Q | J29: =IF(J30>0,IF(J32>G32,"上方修正",IF(J32<G32,"下方修正","据え置き")),"") | K29: 前期比 | L29: ３Q | M29: =IF(M30>0,IF(M32>J32,"上方修正",IF(M32<J32,"下方修正","据え置き")),"") | N29: 前期比 | O29: 実績 | P29: =IF(P30>0,IF(P32>M32,"上方修正",IF(P32<M32,"下方修正","据え置き")),"") | Q29: 前期比
B30: 売上高 | E30: =IF($M5,D30/$M5,"-") -> 0 | H30: =IF($M5,G30/$M5,"-") -> 0 | K30: =IF($M5,J30/$M5,"-") -> 0 | N30: =IF($M5,M30/$M5,"-") -> 0 | Q30: =IF($M5,P30/$M5,"-") -> 0
B31: 経常利益 | E31: =IF($M10>0,D31/$M10,"-") -> 0 | H31: =IF($M10>0,G31/$M10,"-") -> 0 | K31: =IF($M10>0,J31/$M10,"-") -> 0 | N31: =IF($M10>0,M31/$M10,"-") -> 0 | Q31: =IF($M10>0,P31/$M10,"-") -> 0
B32: 純利益 | E32: =IF($M11>0,D32/$M11,"-") -> 0 | H32: =IF($M11>0,G32/$M11,"-") -> 0 | K32: =IF($M11>0,J32/$M11,"-") -> 0 | N32: =IF($M11>0,M32/$M11,"-") -> 0 | Q32: =IF($M11>0,P32/$M11,"-") -> 0
A34: ■今期四半期決算
C35: 期初 | E35: 前期比 | F35: １Q | H35: 進捗率 | I35: ２Q | K35: 進捗率 | L35: ３Q | N35: 進捗率 | O35: ４Q | Q35: 進捗率
B36: 売上高 | F36: =IF(F30,G36/F30,0) -> 0 | H36: =IF(G30,G36/G30,0) -> 0 | I36: =IF(I30,J36/I30,0) -> 0 | J36: データなし | K36: =IF(J30,J36/J30,0) -> 0 | N36: =IF(M30,M36/M30,0) -> 0 | Q36: =IF(P30,P36/P30,0) -> 0
B37: 経常利益 | F37: =IF(F31,G37/F31,0) -> 0 | H37: =IF(G31,G37/G31,0) -> 0 | I37: =IF(I31,J37/I31,0) -> 0 | J37: データなし | K37: =IF(J31,J37/J31,0) -> 0 | N37: =IF(M31,M37/M31,0) -> 0 | Q37: =IF(P31,P37/P31,0) -> 0
B38: 純利益 | F38: =IF(F32,G38/F32,0) -> 0 | H38: =IF(G32,G38/G32,0) -> 0 | I38: =IF(I32,J38/I32,0) -> 0 | J38: データなし | K38: =IF(J32,J38/J32,0) -> 0 | N38: =IF(M32,M38/M32,0) -> 0 | Q38: =IF(P32,P38/P32,0) -> 0
B40: 発行株数 | D40: =M13 -> 68468 | E40: 千株 | J40: 68468 | Q40: =N40 -> 0
B41: EPS／PER | D41: =IF(D40,D31*1000*0.7/D40,0) -> 0 | E41: =IF(D41,D53/D41,0) -> 0 | G41: =IF(G40,G31*1000*0.7/G40,0) -> 0 | H41: =IF(G41,G53/G41,0) -> 0 | J41: =IF(J40,J31*1000*0.7/J40,0) -> 0 | K41: =IF(J41,J53/J41,0) -> 0 | M41: =IF(M40,M31*1000*0.7/M40,0) -> 0 | N41: =IF(M41,M53/M41,0) -> 0 | P41: =IF(P40,P31*1000*0.7/P40,0) -> 0 | Q41: =IF(P41,P53/P41,0) -> 0
C43: 資産 | D43: 資本 | E43: 負債 | F43: 資産 | G43: 資本 | H43: 負債 | I43: 資産 | J43: 資本 | K43: 負債 | L43: 資産 | M43: 資本 | N43: 負債 | O43: 資産 | P43: 資本 | Q43: 負債
B44: バランスシート | C44: =L17 -> 377771 | D44: =M17 -> 272598 | E44: =C44-D44 -> 105173 | H44: =F44-G44 -> 0 | I44: データなし | J44: データなし | K44: =I44-J44 -> #VALUE! | N44: =L44-M44 -> 0 | Q44: =O44-P44 -> 0
B45: BPS／PBR | C45: =IF(C44,D44/C44,0) -> 0.72159589 | D45: =IF(D40,D44/D40*1000,0) -> 3981.3928 | E45: =IF(D45,D40/D45,0) -> 17.196997 | F45: =IF(F44,G44/F44,0) -> 0 | G45: =IF(G40,G44/G40*1000,0) -> 0 | H45: =IF(G45,G40/G45,0) -> 0 | I45: =IF(I44,J44/I44,0) -> #VALUE! | J45: =IF(J40,J44/J40*1000,0) -> #VALUE! | K45: =IF(J45,J40/J45,0) -> #VALUE! | L45: =IF(L44,M44/L44,0) -> 0 | M45: =IF(M40,M44/M40*1000,0) -> 0 | N45: =IF(M45,M40/M45,0) -> 0 | O45: =IF(O44,P44/O44,0) -> 0 | P45: =IF(P40,P44/P40*1000,0) -> 0 | Q45: =IF(P45,P40/P45,0) -> 0
B46: 財務レバレッジ補正 | C46: =IF(D44*C44>0,IF((1/(D44/C44+0.33))<1,1,IF((1/(D44/C44+0.33))>1.5,1.5,1/(D44/C44+0.33))),0) -> 1 | F46: =IF(G44*F44>0,IF((1/(G44/F44+0.33))<1,1,IF((1/(G44/F44+0.33))>1.5,1.5,1/(G44/F44+0.33))),0) -> 0 | I46: =IF(J44*I44>0,IF((1/(J44/I44+0.33))<1,1,IF((1/(J44/I44+0.33))>1.5,1.5,1/(J44/I44+0.33))),0) -> #VALUE! | L46: =IF(M44*L44>0,IF((1/(M44/L44+0.33))<1,1,IF((1/(M44/L44+0.33))>1.5,1.5,1/(M44/L44+0.33))),0) -> 0 | O46: =IF(P44*O44>0,IF((1/(P44/O44+0.33))<1,1,IF((1/(P44/O44+0.33))>1.5,1.5,1/(P44/O44+0.33))),0) -> 0
...

Sheet 決算分析
K1: コード | L1: 銘柄名 | N1: 決算年 | O1: 決算月 | P1: 更新日
K2: =決算入力!K2 -> 2206 | L2: =決算入力!L2 -> 江崎グリコ株式会社 | N2: =決算入力!N2 -> 2025 | O2: =決算入力!O2 -> 12 | P2: =決算入力!P2 -> 46080.831
A3: ■時系列決算データ比較
C4: =LEFT(F4,4)-1&"年" -> 2021年 | D4: =G4 -> 12 月期 | E4: 構成比 | F4: =LEFT(I4,4)-1&"年" -> 2022年 | G4: =J4 -> 12 月期 | H4: 構成比 | I4: =LEFT(L4,4)-1&"年" -> 2023年 | J4: =M4 -> 12 月期 | K4: 構成比 | L4: =LEFT(O4,4)-1&"年" -> 2024年 | M4: =P4 -> 12 月期 | N4: 構成比 | O4: =N2 &" 年" -> 2025 年 | P4: =O2 &" 月期" -> 12 月期 | Q4: 構成比
B5: 売上高 | D5: =決算入力!D5 -> 338571 | E5: 百万 | G5: =決算入力!G5 -> 303921 | H5: =E5 -> 百万 | J5: =決算入力!J5 -> 332590 | K5: =E5 -> 百万 | M5: =決算入力!M5 -> 331129 | N5: =E5 -> 百万 | P5: =決算入力!P5 -> 0 | Q5: =H5 -> 百万
B6: 売上原価 | D6: =決算入力!D6 -> 180537 | E6: =IF(D$5,D6/D$5,"-") -> 0.53323232 | G6: =決算入力!G6 -> 193172 | H6: =IF(G$5,G6/G$5,"-") -> 0.63559938 | J6: =決算入力!J6 -> 208740 | K6: =IF(J$5,J6/J$5,"-") -> 0.62761959 | M6: =決算入力!M6 -> 203461 | N6: =IF(M$5,M6/M$5,"-") -> 0.61444633 | P6: =決算入力!P6 -> 0 | Q6: =IF(P$5,P6/P$5,"-") -> -
B7: 売上総利益 | D7: =決算入力!D7 -> 158033 | E7: =IF(D$5,D7/D$5,"-") -> 0.46676473 | G7: =決算入力!G7 -> 110749 | H7: =IF(G$5,G7/G$5,"-") -> 0.36440062 | J7: =決算入力!J7 -> 123850 | K7: =IF(J$5,J7/J$5,"-") -> 0.37238041 | M7: =決算入力!M7 -> 127668 | N7: =IF(M$5,M7/M$5,"-") -> 0.38555367 | P7: =決算入力!P7 -> 0 | Q7: =IF(P$5,P7/P$5,"-") -> -
B8: 販管費 | D8: =決算入力!D8 -> 138726 | E8: =IF(D$5,D8/D$5,"-") -> 0.40973976 | G8: =決算入力!G8 -> 97903 | H8: =IF(G$5,G8/G$5,"-") -> 0.32213305 | J8: =決算入力!J8 -> 105228 | K8: =IF(J$5,J8/J$5,"-") -> 0.31638955 | M8: =決算入力!M8 -> 116602 | N8: =IF(M$5,M8/M$5,"-") -> 0.35213467 | P8: =決算入力!P8 -> 0 | Q8: =IF(P$5,P8/P$5,"-") -> -
B9: 営業利益 | D9: =決算入力!D9 -> 19307 | E9: =IF(D$5,D9/D$5,"-") -> 0.057024967 | G9: =決算入力!G9 -> 12845 | H9: =IF(G$5,G9/G$5,"-") -> 0.042264273 | J9: =決算入力!J9 -> 18622 | K9: =IF(J$5,J9/J$5,"-") -> 0.05599086 | M9: =決算入力!M9 -> 11065 | N9: =IF(M$5,M9/M$5,"-") -> 0.03341598 | P9: =決算入力!P9 -> 0 | Q9: =IF(P$5,P9/P$5,"-") -> -
B10: 経常利益 | D10: =決算入力!D10 -> 21708 | E10: =IF(D$5,D10/D$5,"-") -> 0.064116537 | G10: =決算入力!G10 -> 13646 | H10: =IF(G$5,G10/G$5,"-") -> 0.044899826 | J10: =決算入力!J10 -> 21285 | K10: =IF(J$5,J10/J$5,"-") -> 0.063997715 | M10: =決算入力!M10 -> 13348 | N10: =IF(M$5,M10/M$5,"-") -> 0.040310574 | P10: =決算入力!P10 -> 0 | Q10: =IF(P$5,P10/P$5,"-") -> -
B11: 純利益 | D11: =決算入力!D11 -> 13567 | E11: =IF(D$5,D11/D$5,"-") -> 0.040071359 | G11: =決算入力!G11 -> 8156 | H11: =IF(G$5,G11/G$5,"-") -> 0.026835921 | J11: =決算入力!J11 -> 14219 | K11: =IF(J$5,J11/J$5,"-") -> 0.042752338 | M11: =決算入力!M11 -> 8157 | N11: =IF(M$5,M11/M$5,"-") -> 0.024633904 | P11: =決算入力!P11 -> 0 | Q11: =IF(P$5,P11/P$5,"-") -> -
B13: 発行株数 | D13: =決算入力!D13 -> 68468 | E13: 千株 | G13: =決算入力!G13 -> 68468 | H13: =E13 -> 千株 | J13: =決算入力!J13 -> 68468 | K13: =H13 -> 千株 | M13: =決算入力!M13 -> 68468 | N13: =K13 -> 千株 | P13: =決算入力!P13 -> 68468 | Q13: =N13 -> 千株
B14: ＥＰＳ／ＰＥＲ | D14: =決算入力!D14 -> 221.93726 | E14: =決算入力!E14 -> 0 | G14: =決算入力!G14 -> 139.51335 | H14: =決算入力!H14 -> 0 | J14: =決算入力!J14 -> 217.61261 | K14: =決算入力!K14 -> 0 | M14: =決算入力!M14 -> 136.46667 | N14: =決算入力!N14 -> 0 | P14: =決算入力!P14 -> 0 | Q14: =決算入力!Q14 -> 0
C16: 資産 | D16: 資本 | E16: 負債 | F16: 資産 | G16: 資本 | H16: 負債 | I16: 資産 | J16: 資本 | K16: 負債 | L16: 資産 | M16: 資本 | N16: 負債 | O16: 資産 | P16: 資本 | Q16: 負債
B17: バランスシート | C17: =決算入力!C17 -> 356745 | D17: =決算入力!D17 -> 241177 | E17: =C17-D17 -> 115568 | F17: =決算入力!F17 -> 369056 | G17: =決算入力!G17 -> 244760 | H17: =F17-G17 -> 124296 | I17: =決算入力!I17 -> 395743 | J17: =決算入力!J17 -> 263116 | K17: =I17-J17 -> 132627 | L17: =決算入力!L17 -> 377771 | M17: =決算入力!M17 -> 272598 | N17: =L17-M17 -> 105173 | O17: =決算入力!O17 -> #VALUE! | P17: =決算入力!P17 -> #VALUE! | Q17: =O17-P17 -> #VALUE!
B18: ＢＰＳ／ＰＢＲ | C18: =IF(C17,D17/C17,0) -> 0.67604872 | D18: =IF(D13,D17/D13*1000,0) -> 3522.4777 | E18: =決算入力!E18 -> 0 | F18: =IF(F17,G17/F17,0) -> 0.66320558 | G18: =IF(G13,G17/G13*1000,0) -> 3574.8087 | H18: =決算入力!H18 -> 0 | I18: =IF(I17,J17/I17,0) -> 0.66486583 | J18: =IF(J13,J17/J13*1000,0) -> 3842.9047 | K18: =決算入力!K18 -> 0 | L18: =IF(L17,M17/L17,0) -> 0.72159589 | M18: =IF(M13,M17/M13*1000,0) -> 3981.3928 | N18: =決算入力!N18 -> 0 | O18: =IF(O17,P17/O17,0) -> #VALUE! | P18: =IF(P13,P17/P13*1000,0) -> #VALUE! | Q18: =決算入力!Q18 -> #VALUE!
C19: =IF(D17*C17>0,IF((1/(D17/C17+0.33))<1,1,IF((1/(D17/C17+0.33))>1.5,1.5,1/(D17/C17+0.33))),0) -> 1 | F19: =IF(G17*F17>0,IF((1/(G17/F17+0.33))<1,1,IF((1/(G17/F17+0.33))>1.5,1.5,1/(G17/F17+0.33))),0) -> 1.0068409 | I19: =IF(J17*I17>0,IF((1/(J17/I17+0.33))<1,1,IF((1/(J17/I17+0.33))>1.5,1.5,1/(J17/I17+0.33))),0) -> 1.0051607 | L19: =IF(M17*L17>0,IF((1/(M17/L17+0.33))<1,1,IF((1/(M17/L17+0.33))>1.5,1.5,1/(M17/L17+0.33))),0) -> 1 | O19: =IF(P17*O17>0,IF((1/(P17/O17+0.33))<1,1,IF((1/(P17/O17+0.33))>1.5,1.5,1/(P17/O17+0.33))),0) -> #VALUE!
C20: 営業 | D20: 投資 | E20: 財務 | F20: 営業 | G20: 投資 | H20: 財務 | I20: 営業 | J20: 投資 | K20: 財務 | L20: 営業 | M20: 投資 | N20: 財務 | O20: 営業 | P20: 投資 | Q20: 財務
B21: キャッシュフロー | C21: =決算入力!C21 -> 28651 | D21: =決算入力!D21 -> -29194 | E21: =決算入力!E21 -> -4859 | F21: =決算入力!F21 -> 16802 | G21: =決算入力!G21 -> -20140 | H21: =決算入力!H21 -> -10284 | I21: =決算入力!I21 -> 28063 | J21: =決算入力!J21 -> -8613 | ... Q21: =決算入力!Q21 -> #VALUE!
B22: 現金残／ＦＣＦ | D22: =決算入力!D22 -> 89463 | E22: =決算入力!E22 -> -543 | G22: =決算入力!G22 -> 79917 | H22: =決算入力!H22 -> -3338 | J22: =決算入力!J22 -> 94691 | K22: =決算入力!K22 -> 19450 | M22: =決算入力!M22 -> 56610 | N22: =決算入力!N22 -> -8443 | P22: =決算入力!P22 -> #VALUE! | Q22: =決算入力!Q22 -> #VALUE!
A51: ■時系列比較データ
C52: 売上 | H52: 売上増収率 | L52: 前期比 | M52: 売上増収率 | Q52: ３期前比較
B53: 売上 | C53: ４期前 | D53: ３期前 | E53: ２期前 | F53: 前期 | G53: （今期） | H53: ４期前 | I53: ３期前 | J53: ２期前 | K53: 前期 | L53: （今期） | M53: ４期前 | N53: ３期前 | O53: ２期前 | P53: 前期 | Q53: （今期）
B54: =N2 -> 2025 | C54: =D5 -> 338571 | D54: =G5 -> 303921 | E54: =J5 -> 332590 | F54: =M5 -> 331129 | G54: =P5 -> 0 | H54: - | I54: =IF(C54,D54/C54,"-") -> 0.8976581 | J54: =IF(D54,E54/D54,"-") -> 1.0943304 | K54: =IF(E54,F54/E54,"-") -> 0.9956072 | L54: =IF(F54,G54/F54,"-") -> 0 | M54: =IF($C54,C54/$C54,"-") -> 1 | N54: =IF($C54,D54/$C54,"-") -> 0.8976581 | O54: =IF($C54,E54/$C54,"-") -> 0.98233458 | P54: =IF($C54,F54/$C54,"-") -> 0.97801938 | Q54: =IF($C54,G54/$C54,"-") -> 0
C56: 経常利益 | H56: 経常増益率 | L56: 前期比 | M56: 経常増益率 | Q56: ３期前比較
B57: 経常利益 | C57: ４期前 | D57: ３期前 | E57: ２期前 | F57: 前期 | G57: （今期） | H57: ４期前 | I57: ３期前 | J57: ２期前 | K57: 前期 | L57: （今期） | M57: ４期前 | N57: ３期前 | O57: ２期前 | P57: 前期 | Q57: （今期）
B58: =B$54 -> 2025 | C58: =D10 -> 21708 | D58: =G10 -> 13646 | E58: =J10 -> 21285 | F58: =M10 -> 13348 | G58: =P10 -> 0 | H58: - | I58: =IF(C58,D58/C58,"-") -> 0.62861618 | J58: =IF(D58,E58/D58,"-") -> 1.5597977 | K58: =IF(E58,F58/E58,"-") -> 0.62710829 | L58: =IF(F58,G58/F58,"-") -> 0 | M58: =IF($C58,C58/$C58,"-") -> 1 | N58: =IF($C58,D58/$C58,"-") -> 0.62861618 | O58: =IF($C58,E58/$C58,"-") -> 0.9805141 | P58: =IF($C58,F58/$C58,"-") -> 0.61488852 | Q58: =IF($C58,G58/$C58,"-") -> 0
C60: 株価 | H60: 株価上昇率 | L60: 前期比 | M60: 株価上昇率 | Q60: ３期前比較
B61: 株価 | C61: ４期前 | D61: ３期前 | E61: ２期前 | F61: 前期 | G61: （今期） | H61: ４期前 | I61: ３期前 | J61: ２期前 | K61: 前期 | L61: （今期） | M61: ４期前 | N61: ３期前 | O61: ２期前 | P61: 前期 | Q61: （今期）
B62: =B$54 -> 2025 | C62: =決算入力!D26 -> 0 | D62: =決算入力!G26 -> 0 | E62: =決算入力!J26 -> 0 | F62: =決算入力!M26 -> 0 | G62: =決算入力!P26 -> 0 | H62: - | I62: =IF(C62,D62/C62,"-") -> - | J62: =IF(D62,E62/D62,"-") -> - | K62: =IF(E62,F62/E62,"-") -> - | L62: =IF(F62,G62/F62,"-") -> - | M62: =IF($C62,C62/$C62,"-") -> - | N62: =IF($C62,D62/$C62,"-") -> - | O62: =IF($C62,E62/$C62,"-") -> - | P62: =IF($C62,F62/$C62,"-") -> - | Q62: =IF($C62,G62/$C62,"-") -> -
C64: 発行株数 | H64: 発行株数増加率 | L64: 前期比 | M64: 発行株数増加率 | Q64: ３期前比較
B65: 発行株数 | C65: ４期前 | D65: ３期前 | E65: ２期前 | F65: 前期 | G65: （今期） | H65: ４期前 | I65: ３期前 | J65: ２期前 | K65: 前期 | L65: （今期） | M65: ４期前 | N65: ３期前 | O65: ２期前 | P65: 前期 | Q65: （今期）
B66: =B$54 -> 2025 | C66: =D13 -> 68468 | D66: =G13 -> 68468 | E66: =J13 -> 68468 | F66: =M13 -> 68468 | G66: =P13 -> 68468 | H66: - | I66: =IF(C66,D66/C66,"-") -> 1 | J66: =IF(D66,E66/D66,"-") -> 1 | K66: =IF(E66,F66/E66,"-") -> 1 | L66: =IF(F66,G66/F66,"-") -> 1 | M66: =IF($C66,C66/$C66,"-") -> 1 | N66: =IF($C66,D66/$C66,"-") -> 1 | O66: =IF($C66,E66/$C66,"-") -> 1 | P66: =IF($C66,F66/$C66,"-") -> 1 | Q66: =IF($C66,G66/$C66,"-") -> 1
C68: 時価総額 | H68: 時価総額増加率 | L68: 前期比 | M68: 時価総額増加率 | Q68: ３期前比較
B69: 時価総額 | C69: ４期前 | D69: ３期前 | E69: ２期前 | F69: 前期 | G69: （今期） | H69: ４期前 | I69: ３期前 | J69: ２期前 | K69: 前期 | L69: （今期） | M69: ４期前 | N69: ３期前 | O69: ２期前 | P69: 前期 | Q69: （今期）
B70: =B$54 -> 2025 | C70: =C62*C66/1000 -> 0 | D70: =D62*D66/1000 -> 0 | E70: =E62*E66/1000 -> 0 | F70: =F62*F66/1000 -> 0 | G70: =G62*G66/1000 -> 0 | H70: - | I70: =IF(C70,D70/C70,0) -> 0 | J70: =IF(D70,E70/D70,0) -> 0 | K70: =IF(E70,F70/E70,0) -> 0 | L70: =IF(F70,G70/F70,0) -> 0 | M70: =IF($C70,C70/$C70,0) -> 0 | N70: =IF($C70,D70/$C70,0) -> 0 | O70: =IF($C70,E70/$C70,0) -> 0 | P70: =IF($C70,F70/$C70,0) -> 0 | Q70: =IF($C70,G70/$C70,0) -> 0
C72: ＥＰＳ | E72: (経常*30%) | H72: ＥＰＳ増加率 | L72: 前期比 | M72: ＥＰＳ増加率 | Q72: ３期前比較
B73: ＥＰＳ | C73: ４期前 | D73: ３期前 | E73: ２期前 | F73: 前期 | G73: （今期） | H73: ４期前 | I73: ３期前 | J73: ２期前 | K73: 前期 | L73: （今期） | M73: ４期前 | N73: ３期前 | O73: ２期前 | P73: 前期 | Q73: （今期）
B74: =B$54 -> 2025 | C74: =IF(C66,(C58*0.7)*1000/C66,0) -> 221.93726 | D74: =IF(D66,(D58*0.7)*1000/D66,0) -> 139.51335 | E74: =IF(E66,(E58*0.7)*1000/E66,0) -> 217.61261 | F74: =IF(F66,(F58*0.7)*1000/F66,0) -> 136.46667 | G74: =IF(G66,(G58*0.7)*1000/G66,0) -> 0 | H74: - | I74: =IF(C74,D74/C74,0) -> 0.62861618 | J74: =IF(D74,E74/D74,0) -> 1.5597977 | K74: =IF(E74,F74/E74,0) -> 0.62710829 | L74: =IF(F74,G74/F74,0) -> 0 | M74: =IF($C74,C74/$C74,0) -> 1 | N74: =IF($C74,D74/$C74,0) -> 0.62861618 | O74: =IF($C74,E74/$C74,0) -> 0.9805141 | P74: =IF($C74,F74/$C74,0) -> 0.61488852 | Q74: =IF($C74,G74/$C74,0) -> 0
C76: 現金残 | H76: 現金残増加率 | L76: 前期比 | M76: 現金残増加率 | Q76: ３期前比較
...

Sheet メモ
A1: ・ | B1: 増減率について
B2: 赤字から黒字になった場合：-(ハイフン)
B3: 黒字から赤字になった場合：-(ハイフン)
B4: 0から増減した場合：-(ハイフン)

Sheet 決算入力 (2)
K1: コード | L1: 銘柄名 | N1: 決算年 | O1: 決算月 | P1: 更新日
P2: =NOW() -> 46080.831
A3: ■時系列決算データ比較
C4: =LEFT(F4,4)-1&"年" -> #VALUE! | D4: =G4 -> 月期 | E4: 構成比 | F4: =LEFT(I4,4)-1&"年" -> #VALUE! | G4: =J4 -> 月期 | H4: 構成比 | I4: =LEFT(L4,4)-1&"年" -> #VALUE! | J4: =M4 -> 月期 | K4: 構成比 | L4: =LEFT(O4,4)-1&"年" -> #VALUE! | M4: =P4 -> 月期 | N4: 構成比 | O4: =N2 &" 年" -> 年 | P4: =O2 &" 月期" -> 月期 | Q4: 構成比
B5: 売上高 | E5: 百万 | H5: =E5 -> 百万 | K5: =E5 -> 百万 | N5: =E5 -> 百万 | P5: =IF(P30,P30,IF(M30,M30,IF(J30,J30,IF(G30,G30,IF(D30,D30,0))))) -> 0 | Q5: =H5 -> 百万
B6: 売上原価 | E6: =IF(D$5,D6/D$5,"-") -> - | H6: =IF(G$5,G6/G$5,"-") -> - | K6: =IF(J$5,J6/J$5,"-") -> - | N6: =IF(M$5,M6/M$5,"-") -> - | Q6: =IF(P$5,P6/P$5,"-") -> -
B7: 売上総利益 | E7: =IF(D$5,D7/D$5,"-") -> - | H7: =IF(G$5,G7/G$5,"-") -> - | K7: =IF(J$5,J7/J$5,"-") -> - | N7: =IF(M$5,M7/M$5,"-") -> - | Q7: =IF(P$5,P7/P$5,"-") -> -
B8: 販管費 | E8: =IF(D$5,D8/D$5,"-") -> - | H8: =IF(G$5,G8/G$5,"-") -> - | K8: =IF(J$5,J8/J$5,"-") -> - | N8: =IF(M$5,M8/M$5,"-") -> - | Q8: =IF(P$5,P8/P$5,"-") -> -
B9: 営業利益 | E9: =IF(D$5,D9/D$5,"-") -> - | H9: =IF(G$5,G9/G$5,"-") -> - | K9: =IF(J$5,J9/J$5,"-") -> - | N9: =IF(M$5,M9/M$5,"-") -> - | Q9: =IF(P$5,P9/P$5,"-") -> -
B10: 経常利益 | E10: =IF(D$5,D10/D$5,"-") -> - | H10: =IF(G$5,G10/G$5,"-") -> - | K10: =IF(J$5,J10/J$5,"-") -> - | N10: =IF(M$5,M10/M$5,"-") -> - | P10: =IF(P31,P31,IF(M31,M31,IF(J31,J31,IF(G31,G31,IF(D31,D31,0))))) -> 0 | Q10: =IF(P$5,P10/P$5,"-") -> -
B11: 純利益 | E11: =IF(D$5,D11/D$5,"-") -> - | H11: =IF(G$5,G11/G$5,"-") -> - | K11: =IF(J$5,J11/J$5,"-") -> - | N11: =IF(M$5,M11/M$5,"-") -> - | P11: =IF(P32,P32,IF(M32,M32,IF(J32,J32,IF(G32,G32,IF(D32,D32,0))))) -> 0 | Q11: =IF(P$5,P11/P$5,"-") -> -
B13: 発行株数 | E13: 千株 | H13: =E13 -> 千株 | K13: =H13 -> 千株 | N13: =K13 -> 千株 | P13: =IF(P40,P40,IF(M40,M40,IF(J40,J40,IF(G40,G40,IF(D40,D40,0))))) -> 0 | Q13: =N13 -> 千株
B14: EPS／PER | D14: =IF(D13,D10*1000*0.7/D13,0) -> 0 | E14: =IF(D14,D26/D14,0) -> 0 | G14: =IF(G13,G10*1000*0.7/G13,0) -> 0 | H14: =IF(G14,G26/G14,0) -> 0 | J14: =IF(J13,J10*1000*0.7/J13,0) -> 0 | K14: =IF(J14,J26/J14,0) -> 0 | M14: =IF(M13,M10*1000*0.7/M13,0) -> 0 | N14: =IF(M14,M26/M14,0) -> 0 | P14: =IF(P13,P10*1000*0.7/P13,0) -> 0 | Q14: =IF(P14,P26/P14,0) -> 0
C16: 資産 | D16: 資本 | E16: 負債 | F16: 資産 | G16: 資本 | H16: 負債 | I16: 資産 | J16: 資本 | K16: 負債 | L16: 資産 | M16: 資本 | N16: 負債 | O16: 資産 | P16: 資本 | Q16: 負債
B17: バランスシート | E17: =C17-D17 -> 0 | H17: =F17-G17 -> 0 | K17: =I17-J17 -> 0 | N17: =L17-M17 -> 0 | O17: =IF(O44,O44,IF(L44,L44,IF(I44,I44,IF(F44,F44,IF(C44,C44,0))))) -> 0 | P17: =IF(P44,P44,IF(M44,M44,IF(J44,J44,IF(G44,G44,IF(D44,D44,0))))) -> 0 | Q17: =O17-P17 -> 0
B18: BPS／PBR | C18: =IF(C17,D17/C17,0) -> 0 | D18: =IF(D13,D17/D13*1000,0) -> 0 | E18: =IF(D18,D26/D18,0) -> 0 | F18: =IF(F17,G17/F17,0) -> 0 | G18: =IF(G13,G17/G13*1000,0) -> 0 | H18: =IF(G18,G26/G18,0) -> 0 | I18: =IF(I17,J17/I17,0) -> 0 | J18: =IF(J13,J17/J13*1000,0) -> 0 | K18: =IF(J18,J26/J18,0) -> 0 | L18: =IF(L17,M17/L17,0) -> 0 | M18: =IF(M13,M17/M13*1000,0) -> 0 | N18: =IF(M18,M26/M18,0) -> 0 | O18: =IF(O17,P17/O17,0) -> 0 | P18: =IF(P13,P17/P13*1000,0) -> 0 | Q18: =IF(P18,P26/P18,0) -> 0
B19: 財務レバレッジ補正 | C19: =IF(D17*C17>0,IF((1/(D17/C17+0.33))<1,1,IF((1/(D17/C17+0.33))>1.5,1.5,1/(D17/C17+0.33))),0) -> 0 | F19: =IF(G17*F17>0,IF((1/(G17/F17+0.33))<1,1,IF((1/(G17/F17+0.33))>1.5,1.5,1/(G17/F17+0.33))),0) -> 0 | I19: =IF(J17*I17>0,IF((1/(J17/I17+0.33))<1,1,IF((1/(J17/I17+0.33))>1.5,1.5,1/(J17/I17+0.33))),0) -> 0 | L19: =IF(M17*L17>0,IF((1/(M17/L17+0.33))<1,1,IF((1/(M17/L17+0.33))>1.5,1.5,1/(M17/L17+0.33))),0) -> 0 | O19: =IF(P17*O17>0,IF((1/(P17/O17+0.33))<1,1,IF((1/(P17/O17+0.33))>1.5,1.5,1/(P17/O17+0.33))),0) -> 0
C20: 営業 | D20: 投資 | E20: 財務 | F20: 営業 | G20: 投資 | H20: 財務 | I20: 営業 | J20: 投資 | K20: 財務 | L20: 営業 | M20: 投資 | N20: 財務 | O20: 営業 | P20: 投資 | Q20: 財務
B21: キャッシュフロー | O21: =IF(O48,O48,IF(L48,L48,IF(I48,I48,IF(F48,F48,IF(C48,C48,0))))) -> 0 | P21: =IF(P48,P48,IF(M48,M48,IF(J48,J48,IF(G48,G48,IF(D48,D48,0))))) -> 0 | Q21: =IF(Q48,Q48,IF(N48,N48,IF(K48,K48,IF(H48,H48,IF(E48,E48,0))))) -> 0
B22: 現金残／FCF | E22: =C21+D21 -> 0 | H22: =F21+G21 -> 0 | K22: =I21+J21 -> 0 | N22: =L21+M21 -> 0 | P22: =IF(P49,P49,IF(M49,M49,IF(J49,J49,IF(G49,G49,IF(D49,D49,0))))) -> 0 | Q22: =O21+P21 -> 0
C24: 資産価値 | D24: 事業価値 | E24: 理論株価 | F24: 資産価値 | G24: 事業価値 | H24: 理論株価 | I24: 資産価値 | J24: 事業価値 | K24: 理論株価 | L24: 資産価値 | M24: 事業価値 | N24: 理論株価 | O24: 資産価値 | P24: 事業価値 | Q24: 理論株価
B25: 理論株価 | C25: =D18*IF(C18>=0.8,0.8,IF(C18>=0.67,0.75,IF(C18>=0.5,0.7,IF(C18>=0.33,0.65,IF(C18>=0.1,0.6,0.5))))) -> 0 | D25: =IF(C19>0,IF(D10>0,IF(D14*C17,D14*(D10*0.7/C17*150),0),0)*C19,0) -> 0 | E25: =C25+D25 -> 0 | F25: =G18*IF(F18>=0.8,0.8,IF(F18>=0.67,0.75,IF(F18>=0.5,0.7,IF(F18>=0.33,0.65,IF(F18>=0.1,0.6,0.5))))) -> 0 | G25: =IF(F19>0,IF(G10>0,IF(G14*F17,G14*(G10*0.7/F17*150),0),0)*F19,0) -> 0 | H25: =F25+G25 -> 0 | I25: =J18*IF(I18>=0.8,0.8,IF(I18>=0.67,0.75,IF(I18>=0.5,0.7,IF(I18>=0.33,0.65,IF(I18>=0.1,0.6,0.5))))) -> 0 | J25: =IF(I19>0,IF(J10>0,IF(J14*I17,J14*(J10*0.7/I17*150),0),0)*I19,0) -> 0 | K25: =I25+J25 -> 0 | L25: =M18*IF(L18>=0.8,0.8,IF(L18>=0.67,0.75,IF(L18>=0.5,0.7,IF(L18>=0.33,0.65,IF(L18>=0.1,0.6,0.5))))) -> 0 | M25: =IF(L19>0,IF(M10>0,IF(M14*L17,M14*(M10*0.7/L17*150),0),0)*L19,0) -> 0 | N25: =L25+M25 -> 0 | O25: =P18*IF(O18>=0.8,0.8,IF(O18>=0.67,0.75,IF(O18>=0.5,0.7,IF(O18>=0.33,0.65,IF(O18>=0.1,0.6,0.5))))) -> 0 | P25: =IF(O19>0,IF(P10>0,IF(P14*O17,P14*(P10*0.7/O17*150),0),0)*O19,0) -> 0 | Q25: =O25+P25 -> 0
B26: 株価／理論比 | C26: =DATE(LEFT(C4,4),LEFT(D4,LEN(D4)-2)+1,0) -> #VALUE! | E26: =IF(E25,D26/E25,0) -> 0 | F26: =DATE(LEFT(F4,4),LEFT(G4,LEN(G4)-2)+1,0) -> #VALUE! | H26: =IF(H25,G26/H25,0) -> 0 | I26: =DATE(LEFT(I4,4),LEFT(J4,LEN(J4)-2)+1,0) -> #VALUE! | K26: =IF(K25,J26/K25,0) -> 0 | L26: =DATE(LEFT(L4,4),LEFT(M4,LEN(M4)-2)+1,0) -> #VALUE! | N26: =IF(N25,M26/N25,0) -> 0 | O26: =IF(P53,O53,TODAY()) -> 46080 | P26: =IF(P53,P53,IF(M53,M53,IF(J53,J53,IF(G53,G53,IF(D53,D53,0))))) -> 0 | Q26: =IF(Q25,P26/Q25,0) -> 0
B27: 上限理論株価 | C27: =C25+(D25*2) -> 0 | F27: =F25+(G25*2) -> 0 | I27: =I25+(J25*2) -> 0 | L27: =L25+(M25*2) -> 0 | O27: =O25+(P25*2) -> 0
A28: ■今期会社予想
C29: 期初 | E29: 前期比 | F29: １Q | G29: =IF(G30>0,IF(G32>D32,"上方修正",IF(G32<D32,"下方修正","据え置き")),"") | H29: 前期比 | I29: ２Q | J29: =IF(J30>0,IF(J32>G32,"上方修正",IF(J32<G32,"下方修正","据え置き")),"") | K29: 前期比 | L29: ３Q | M29: =IF(M30>0,IF(M32>J32,"上方修正",IF(M32<J32,"下方修正","据え置き")),"") | N29: 前期比 | O29: 実績 | P29: =IF(P30>0,IF(P32>M32,"上方修正",IF(P32<M32,"下方修正","据え置き")),"") | Q29: 前期比
B30: 売上高 | E30: =IF($M5,D30/$M5,"-") -> - | H30: =IF($M5,G30/$M5,"-") -> - | K30: =IF($M5,J30/$M5,"-") -> - | N30: =IF($M5,M30/$M5,"-") -> - | Q30: =IF($M5,P30/$M5,"-") -> -
B31: 経常利益 | E31: =IF($M10>0,D31/$M10,"-") -> - | H31: =IF($M10>0,G31/$M10,"-") -> - | K31: =IF($M10>0,J31/$M10,"-") -> - | N31: =IF($M10>0,M31/$M10,"-") -> - | Q31: =IF($M10>0,P31/$M10,"-") -> -
B32: 純利益 | E32: =IF($M11>0,D32/$M11,"-") -> - | H32: =IF($M11>0,G32/$M11,"-") -> - | K32: =IF($M11>0,J32/$M11,"-") -> - | N32: =IF($M11>0,M32/$M11,"-") -> - | Q32: =IF($M11>0,P32/$M11,"-") -> -
A34: ■今期四半期決算
C35: 期初 | E35: 前期比 | F35: １Q | H35: 進捗率 | I35: ２Q | K35: 進捗率 | L35: ３Q | N35: 進捗率 | O35: ４Q | Q35: 進捗率
B36: 売上高 | F36: =IF(F30,G36/F30,0) -> 0 | H36: =IF(G30,G36/G30,0) -> 0 | I36: =IF(I30,J36/I30,0) -> 0 | K36: =IF(J30,J36/J30,0) -> 0 | N36: =IF(M30,M36/M30,0) -> 0 | Q36: =IF(P30,P36/P30,0) -> 0
B37: 経常利益 | F37: =IF(F31,G37/F31,0) -> 0 | H37: =IF(G31,G37/G31,0) -> 0 | I37: =IF(I31,J37/I31,0) -> 0 | K37: =IF(J31,J37/J31,0) -> 0 | N37: =IF(M31,M37/M31,0) -> 0 | Q37: =IF(P31,P37/P31,0) -> 0
B38: 純利益 | F38: =IF(F32,G38/F32,0) -> 0 | H38: =IF(G32,G38/G32,0) -> 0 | I38: =IF(I32,J38/I32,0) -> 0 | K38: =IF(J32,J38/J32,0) -> 0 | N38: =IF(M32,M38/M32,0) -> 0 | Q38: =IF(P32,P38/P32,0) -> 0
B40: 発行株数 | D40: =M13 -> 0 | E40: 千株 | Q40: =N40 -> 0
B41: EPS／PER | D41: =IF(D40,D31*1000*0.7/D40,0) -> 0 | E41: =IF(D41,D53/D41,0) -> 0 | G41: =IF(G40,G31*1000*0.7/G40,0) -> 0 | H41: =IF(G41,G53/G41,0) -> 0 | J41: =IF(J40,J31*1000*0.7/J40,0) -> 0 | K41: =IF(J41,J53/J41,0) -> 0 | M41: =IF(M40,M31*1000*0.7/M40,0) -> 0 | N41: =IF(M41,M53/M41,0) -> 0 | P41: =IF(P40,P31*1000*0.7/P40,0) -> 0 | Q41: =IF(P41,P53/P41,0) -> 0
C43: 資産 | D43: 資本 | E43: 負債 | F43: 資産 | G43: 資本 | H43: 負債 | I43: 資産 | J43: 資本 | K43: 負債 | L43: 資産 | M43: 資本 | N43: 負債 | O43: 資産 | P43: 資本 | Q43: 負債
B44: バランスシート | C44: =L17 -> 0 | D44: =M17 -> 0 | E44: =C44-D44 -> 0 | H44: =F44-G44 -> 0 | K44: =I44-J44 -> 0 | N44: =L44-M44 -> 0 | Q44: =O44-P44 -> 0
B45: BPS／PBR | C45: =IF(C44,D44/C44,0) -> 0 | D45: =IF(D40,D44/D40*1000,0) -> 0 | E45: =IF(D45,D40/D45,0) -> 0 | F45: =IF(F44,G44/F44,0) -> 0 | G45: =IF(G40,G44/G40*1000,0) -> 0 | H45: =IF(G45,G40/G45,0) -> 0 | I45: =IF(I44,J44/I44,0) -> 0 | J45: =IF(J40,J44/J40*1000,0) -> 0 | K45: =IF(J45,J40/J45,0) -> 0 | L45: =IF(L44,M44/L44,0) -> 0 | M45: =IF(M40,M44/M40*1000,0) -> 0 | N45: =IF(M45,M40/M45,0) -> 0 | O45: =IF(O44,P44/O44,0) -> 0 | P45: =IF(P40,P44/P40*1000,0) -> 0 | Q45: =IF(P45,P40/P45,0) -> 0
B46: 財務レバレッジ補正 | C46: =IF(D44*C44>0,IF((1/(D44/C44+0.33))<1,1,IF((1/(D44/C44+0.33))>1.5,1.5,1/(D44/C44+0.33))),0) -> 0 | F46: =IF(G44*F44>0,IF((1/(G44/F44+0.33))<1,1,IF((1/(G44/F44+0.33))>1.5,1.5,1/(G44/F44+0.33))),0) -> 0 | I46: =IF(J44*I44>0,IF((1/(J44/I44+0.33))<1,1,IF((1/(J44/I44+0.33))>1.5,1.5,1/(J44/I44+0.33))),0) -> 0 | L46: =IF(M44*L44>0,IF((1/(M44/L44+0.33))<1,1,IF((1/(M44/L44+0.33))>1.5,1.5,1/(M44/L44+0.33))),0) -> 0 | O46: =IF(P44*O44>0,IF((1/(P44/O44+0.33))<1,1,IF((1/(P44/O44+0.33))>1.5,1.5,1/(P44/O44+0.33))),0) -> 0
...

Sheet Sheet2
A2: 以下のようなXBRLファイル内タグを使ってエクセルに書き込みたいです。 | K2: XBRLファイル内タグの「contextRef」については以下の種類を使います。
A3: ※ほかにも違う種類のタグがあれば対応できるようにしたい | K3: なお、以下のものは私が把握している限りのものです。ほかにも違う種類があれば対応できるようにしたい。
A4: ※会計基準のIFRSも含む | K4: CurrentYearDuration_NonConsolidatedMember
A5: エクセル表記 | B5: タグ | K5: CurrentYearDuration
A6: 銘柄名 | B6: jpcrp_cor:CompanyNameCoverPage | K6: CurrentYearInstant_NonConsolidatedMember
A7: 決算年 | B7: jpdei_cor:CurrentFiscalYearEndDateDEI | K7: CurrentYearInstant
A8: 決算月 | B8: CurrentFiscalYearEndDateDEIyear | K8: CurrentYTDDuration_NonConsolidatedMember
A9: 売上高 | B9: jppfs_cor:NetSales、jpigp_cor:RevenueIFRS、jpigp_cor:NetSalesIFRS、jpcrp030000-asr_E02144-000:TotalNetRevenuesIFRS | K9: CurrentYTDDuration
A10: 売上原価 | B10: jppfs_cor:CostOfSales、jpigp_cor:CostOfSalesIFRS | K10: CurrentQuarterInstant_NonConsolidatedMember
A11: 売上総利益 | B11: jppfs_cor:GrossProfit、jpigp_cor:GrossProfitIFRS | K11: CurrentQuarterInstant
A12: 販管費 | B12: jppfs_cor:SellingGeneralAndAdministrativeExpenses、jpigp_cor:SellingGeneralAndAdministrativeExpensesIFRS | K12: InterimDuration_NonConsolidatedMember
A13: 営業利益 | B13: jppfs_cor:OperatingIncome、jpigp_cor:OperatingProfitLossIFRS | K13: InterimDuration
A14: 経常利益 | B14: jppfs_cor:OrdinaryIncome、jpigp_cor:ProfitLossBeforeTaxIFRS
A15: 純利益 | B15: jppfs_cor:ProfitLoss、jpigp_cor:ProfitLossIFRS
A16: 発行株数 | B16: jpcrp_cor:TotalNumberOfIssuedSharesSummaryOfBusinessResults、jpcrp_cor:NumberOfIssuedSharesAsOfFiscalYearEndIssuedSharesTotalNumberOfSharesEtc
A17: 資産 | B17: jpcrp_cor:TotalAssetsSummaryOfBusinessResults、jpcrp_cor:TotalAssetsIFRSSummaryOfBusinessResults、jpigp_cor:AssetsIFRS
A18: 資本 | B18: jpcrp_cor:NetAssetsSummaryOfBusinessResults、jpcrp_cor:EquityAttributableToOwnersOfParentIFRSSummaryOfBusinessResults、jpigp_cor:EquityAttributableToOwnersOfParentIFRS
A19: 営業cf | B19: jppfs_cor:NetCashProvidedByUsedInOperatingActivities、jpigp_cor:NetCashProvidedByUsedInOperatingActivitiesIFRS
A20: 投資cf | B20: jppfs_cor:NetCashProvidedByUsedInInvestmentActivities、jpigp_cor:NetCashProvidedByUsedInInvestingActivitiesIFRS
A21: 財務cf | B21: jppfs_cor:NetCashProvidedByUsedInFinancingActivities、jpigp_cor:NetCashProvidedByUsedInFinancingActivitiesIFRS
A22: 現金残／FCF | B22: jppfs_cor:CashAndCashEquivalents、jpigp_cor:CashAndCashEquivalentsIFRS
A23: 短期借 | B23: jppfs_cor:NetIncreaseDecreaseInShortTermLoansPayableFinCF
A24: 長期借 | B24: jppfs_cor:ProceedsFromLongTermLoansPayableFinCF
A25: 社債 | B25: jppfs_cor:ProceedsFromIssuanceOfBondsFinCF
... A33: コード | B33: jpdei_cor:SecurityCodeDEI
